distributed.nanny - INFO -         Start Nanny at: 'tcp://10.19.2.1:40091'
distributed.nanny - INFO -         Start Nanny at: 'tcp://10.19.2.1:44109'
distributed.nanny - INFO -         Start Nanny at: 'tcp://10.19.2.1:39256'
distributed.nanny - INFO -         Start Nanny at: 'tcp://10.19.2.1:42043'
distributed.nanny - INFO - Closing Nanny at 'tcp://10.19.2.1:40091'
distributed.nanny - INFO - Closing Nanny at 'tcp://10.19.2.1:44109'
distributed.nanny - INFO - Closing Nanny at 'tcp://10.19.2.1:39256'
distributed.nanny - INFO - Closing Nanny at 'tcp://10.19.2.1:42043'
distributed.nanny - WARNING - Worker process still alive after 0 seconds, killing
distributed.nanny - WARNING - Worker process still alive after 0 seconds, killing
distributed.nanny - WARNING - Worker process still alive after 0 seconds, killing
distributed.nanny - WARNING - Worker process still alive after 0 seconds, killing
distributed.dask_worker - INFO - End worker
Traceback (most recent call last):
  File "/home/users/kipnisal/CJinstalled/miniconda/lib/python3.7/site-packages/distributed/core.py", line 271, in _
    await asyncio.wait_for(self.start(), timeout=timeout)
  File "/home/users/kipnisal/CJinstalled/miniconda/lib/python3.7/asyncio/tasks.py", line 449, in wait_for
    raise futures.TimeoutError()
concurrent.futures._base.TimeoutError

During handling of the above exception, another exception occurred:

Traceback (most recent call last):
  File "/home/users/kipnisal/CJinstalled/miniconda/lib/python3.7/runpy.py", line 193, in _run_module_as_main
    "__main__", mod_spec)
  File "/home/users/kipnisal/CJinstalled/miniconda/lib/python3.7/runpy.py", line 85, in _run_code
    exec(code, run_globals)
  File "/home/users/kipnisal/CJinstalled/miniconda/lib/python3.7/site-packages/distributed/cli/dask_worker.py", line 469, in <module>
    go()
  File "/home/users/kipnisal/CJinstalled/miniconda/lib/python3.7/site-packages/distributed/cli/dask_worker.py", line 465, in go
    main()
  File "/home/users/kipnisal/CJinstalled/miniconda/lib/python3.7/site-packages/click/core.py", line 829, in __call__
    return self.main(*args, **kwargs)
  File "/home/users/kipnisal/CJinstalled/miniconda/lib/python3.7/site-packages/click/core.py", line 782, in main
    rv = self.invoke(ctx)
  File "/home/users/kipnisal/CJinstalled/miniconda/lib/python3.7/site-packages/click/core.py", line 1066, in invoke
    return ctx.invoke(self.callback, **ctx.params)
  File "/home/users/kipnisal/CJinstalled/miniconda/lib/python3.7/site-packages/click/core.py", line 610, in invoke
    return callback(*args, **kwargs)
  File "/home/users/kipnisal/CJinstalled/miniconda/lib/python3.7/site-packages/distributed/cli/dask_worker.py", line 451, in main
    loop.run_sync(run)
  File "/home/users/kipnisal/CJinstalled/miniconda/lib/python3.7/site-packages/tornado/ioloop.py", line 530, in run_sync
    return future_cell[0].result()
  File "/home/users/kipnisal/CJinstalled/miniconda/lib/python3.7/site-packages/distributed/cli/dask_worker.py", line 445, in run
    await asyncio.gather(*nannies)
  File "/home/users/kipnisal/CJinstalled/miniconda/lib/python3.7/asyncio/tasks.py", line 630, in _wrap_awaitable
    return (yield from awaitable.__await__())
  File "/home/users/kipnisal/CJinstalled/miniconda/lib/python3.7/site-packages/distributed/core.py", line 277, in _
    type(self).__name__, timeout
concurrent.futures._base.TimeoutError: Nanny failed to start in 60 seconds
distributed.process - INFO - reaping stray process <SpawnProcess(Dask Worker process (from Nanny), started daemon)>
